[2025-07-19T16:31:13.004+0000] {taskinstance.py:1159} INFO - Dependencies all met for dep_context=non-requeueable deps ti=<TaskInstance: restaurant_pipeline.stream_to_bronze scheduled__2025-07-19T16:28:00+00:00 [queued]>
[2025-07-19T16:31:13.010+0000] {taskinstance.py:1159} INFO - Dependencies all met for dep_context=requeueable deps ti=<TaskInstance: restaurant_pipeline.stream_to_bronze scheduled__2025-07-19T16:28:00+00:00 [queued]>
[2025-07-19T16:31:13.010+0000] {taskinstance.py:1361} INFO - Starting attempt 1 of 1
[2025-07-19T16:31:13.018+0000] {taskinstance.py:1382} INFO - Executing <Task(BashOperator): stream_to_bronze> on 2025-07-19 16:28:00+00:00
[2025-07-19T16:31:13.020+0000] {standard_task_runner.py:57} INFO - Started process 732 to run task
[2025-07-19T16:31:13.022+0000] {standard_task_runner.py:84} INFO - Running: ['***', 'tasks', 'run', 'restaurant_pipeline', 'stream_to_bronze', 'scheduled__2025-07-19T16:28:00+00:00', '--job-id', '836', '--raw', '--subdir', 'DAGS_FOLDER/restaurant_pipeline.py', '--cfg-path', '/tmp/tmpbdjg7l3o']
[2025-07-19T16:31:13.024+0000] {standard_task_runner.py:85} INFO - Job 836: Subtask stream_to_bronze
[2025-07-19T16:31:13.049+0000] {task_command.py:416} INFO - Running <TaskInstance: restaurant_pipeline.stream_to_bronze scheduled__2025-07-19T16:28:00+00:00 [running]> on host 28e8e04e957d
[2025-07-19T16:31:13.088+0000] {taskinstance.py:1662} INFO - Exporting env vars: AIRFLOW_CTX_DAG_OWNER='moran' AIRFLOW_CTX_DAG_ID='restaurant_pipeline' AIRFLOW_CTX_TASK_ID='stream_to_bronze' AIRFLOW_CTX_EXECUTION_DATE='2025-07-19T16:28:00+00:00' AIRFLOW_CTX_TRY_NUMBER='1' AIRFLOW_CTX_DAG_RUN_ID='scheduled__2025-07-19T16:28:00+00:00'
[2025-07-19T16:31:13.089+0000] {subprocess.py:63} INFO - Tmp dir root location: /tmp
[2025-07-19T16:31:13.089+0000] {subprocess.py:75} INFO - Running command: ['/bin/bash', '-c', "docker exec -e AIRFLOW_CTX_DAG_RUN_ID='scheduled__2025-07-19T16:28:00+00:00' spark-iceberg spark-submit /home/iceberg/spark/stream_to_bronze.py"]
[2025-07-19T16:31:13.094+0000] {subprocess.py:86} INFO - Output:
[2025-07-19T16:31:14.423+0000] {subprocess.py:93} INFO - 25/07/19 16:31:14 INFO SparkContext: Running Spark version 3.5.6
[2025-07-19T16:31:14.425+0000] {subprocess.py:93} INFO - 25/07/19 16:31:14 INFO SparkContext: OS info Linux, 6.10.14-linuxkit, aarch64
[2025-07-19T16:31:14.425+0000] {subprocess.py:93} INFO - 25/07/19 16:31:14 INFO SparkContext: Java version 17.0.15
[2025-07-19T16:31:14.437+0000] {subprocess.py:93} INFO - 25/07/19 16:31:14 INFO ResourceUtils: ==============================================================
[2025-07-19T16:31:14.438+0000] {subprocess.py:93} INFO - 25/07/19 16:31:14 INFO ResourceUtils: No custom resources configured for spark.driver.
[2025-07-19T16:31:14.438+0000] {subprocess.py:93} INFO - 25/07/19 16:31:14 INFO ResourceUtils: ==============================================================
[2025-07-19T16:31:14.438+0000] {subprocess.py:93} INFO - 25/07/19 16:31:14 INFO SparkContext: Submitted application: StreamToBronze
[2025-07-19T16:31:14.447+0000] {subprocess.py:93} INFO - 25/07/19 16:31:14 INFO ResourceProfile: Default ResourceProfile created, executor resources: Map(cores -> name: cores, amount: 1, script: , vendor: , memory -> name: memory, amount: 1024, script: , vendor: , offHeap -> name: offHeap, amount: 0, script: , vendor: ), task resources: Map(cpus -> name: cpus, amount: 1.0)
[2025-07-19T16:31:14.451+0000] {subprocess.py:93} INFO - 25/07/19 16:31:14 INFO ResourceProfile: Limiting resource is cpu
[2025-07-19T16:31:14.451+0000] {subprocess.py:93} INFO - 25/07/19 16:31:14 INFO ResourceProfileManager: Added ResourceProfile id: 0
[2025-07-19T16:31:14.474+0000] {subprocess.py:93} INFO - 25/07/19 16:31:14 INFO SecurityManager: Changing view acls to: root,spark
[2025-07-19T16:31:14.474+0000] {subprocess.py:93} INFO - 25/07/19 16:31:14 INFO SecurityManager: Changing modify acls to: root,spark
[2025-07-19T16:31:14.475+0000] {subprocess.py:93} INFO - 25/07/19 16:31:14 INFO SecurityManager: Changing view acls groups to:
[2025-07-19T16:31:14.475+0000] {subprocess.py:93} INFO - 25/07/19 16:31:14 INFO SecurityManager: Changing modify acls groups to:
[2025-07-19T16:31:14.475+0000] {subprocess.py:93} INFO - 25/07/19 16:31:14 INFO SecurityManager: SecurityManager: authentication disabled; ui acls disabled; users with view permissions: root, spark; groups with view permissions: EMPTY; users with modify permissions: root, spark; groups with modify permissions: EMPTY
[2025-07-19T16:31:14.502+0000] {subprocess.py:93} INFO - 25/07/19 16:31:14 WARN NativeCodeLoader: Unable to load native-hadoop library for your platform... using builtin-java classes where applicable
[2025-07-19T16:31:14.626+0000] {subprocess.py:93} INFO - 25/07/19 16:31:14 INFO Utils: Successfully started service 'sparkDriver' on port 41427.
[2025-07-19T16:31:14.638+0000] {subprocess.py:93} INFO - 25/07/19 16:31:14 INFO SparkEnv: Registering MapOutputTracker
[2025-07-19T16:31:14.659+0000] {subprocess.py:93} INFO - 25/07/19 16:31:14 INFO SparkEnv: Registering BlockManagerMaster
[2025-07-19T16:31:14.671+0000] {subprocess.py:93} INFO - 25/07/19 16:31:14 INFO BlockManagerMasterEndpoint: Using org.apache.spark.storage.DefaultTopologyMapper for getting topology information
[2025-07-19T16:31:14.672+0000] {subprocess.py:93} INFO - 25/07/19 16:31:14 INFO BlockManagerMasterEndpoint: BlockManagerMasterEndpoint up
[2025-07-19T16:31:14.672+0000] {subprocess.py:93} INFO - 25/07/19 16:31:14 INFO SparkEnv: Registering BlockManagerMasterHeartbeat
[2025-07-19T16:31:14.682+0000] {subprocess.py:93} INFO - 25/07/19 16:31:14 INFO DiskBlockManager: Created local directory at /tmp/blockmgr-47ce878a-cf6b-4d02-8412-cd6a12ac9201
[2025-07-19T16:31:14.688+0000] {subprocess.py:93} INFO - 25/07/19 16:31:14 INFO MemoryStore: MemoryStore started with capacity 434.4 MiB
[2025-07-19T16:31:14.699+0000] {subprocess.py:93} INFO - 25/07/19 16:31:14 INFO SparkEnv: Registering OutputCommitCoordinator
[2025-07-19T16:31:14.749+0000] {subprocess.py:93} INFO - 25/07/19 16:31:14 INFO JettyUtils: Start Jetty 0.0.0.0:4040 for SparkUI
[2025-07-19T16:31:14.773+0000] {subprocess.py:93} INFO - 25/07/19 16:31:14 INFO Utils: Successfully started service 'SparkUI' on port 4040.
[2025-07-19T16:31:14.815+0000] {subprocess.py:93} INFO - 25/07/19 16:31:14 INFO Executor: Starting executor ID driver on host ed7b546796fe
[2025-07-19T16:31:14.815+0000] {subprocess.py:93} INFO - 25/07/19 16:31:14 INFO Executor: OS info Linux, 6.10.14-linuxkit, aarch64
[2025-07-19T16:31:14.816+0000] {subprocess.py:93} INFO - 25/07/19 16:31:14 INFO Executor: Java version 17.0.15
[2025-07-19T16:31:14.818+0000] {subprocess.py:93} INFO - 25/07/19 16:31:14 INFO Executor: Starting executor with user classpath (userClassPathFirst = false): ''
[2025-07-19T16:31:14.819+0000] {subprocess.py:93} INFO - 25/07/19 16:31:14 INFO Executor: Created or updated repl class loader org.apache.spark.util.MutableURLClassLoader@3e1da34 for default.
[2025-07-19T16:31:14.827+0000] {subprocess.py:93} INFO - 25/07/19 16:31:14 INFO Utils: Successfully started service 'org.apache.spark.network.netty.NettyBlockTransferService' on port 33733.
[2025-07-19T16:31:14.827+0000] {subprocess.py:93} INFO - 25/07/19 16:31:14 INFO NettyBlockTransferService: Server created on ed7b546796fe:33733
[2025-07-19T16:31:14.828+0000] {subprocess.py:93} INFO - 25/07/19 16:31:14 INFO BlockManager: Using org.apache.spark.storage.RandomBlockReplicationPolicy for block replication policy
[2025-07-19T16:31:14.833+0000] {subprocess.py:93} INFO - 25/07/19 16:31:14 INFO BlockManagerMaster: Registering BlockManager BlockManagerId(driver, ed7b546796fe, 33733, None)
[2025-07-19T16:31:14.834+0000] {subprocess.py:93} INFO - 25/07/19 16:31:14 INFO BlockManagerMasterEndpoint: Registering block manager ed7b546796fe:33733 with 434.4 MiB RAM, BlockManagerId(driver, ed7b546796fe, 33733, None)
[2025-07-19T16:31:14.835+0000] {subprocess.py:93} INFO - 25/07/19 16:31:14 INFO BlockManagerMaster: Registered BlockManager BlockManagerId(driver, ed7b546796fe, 33733, None)
[2025-07-19T16:31:14.836+0000] {subprocess.py:93} INFO - 25/07/19 16:31:14 INFO BlockManager: Initialized BlockManager: BlockManagerId(driver, ed7b546796fe, 33733, None)
[2025-07-19T16:31:15.045+0000] {subprocess.py:93} INFO - 25/07/19 16:31:15 INFO SharedState: Setting hive.metastore.warehouse.dir ('null') to the value of spark.sql.warehouse.dir.
[2025-07-19T16:31:15.049+0000] {subprocess.py:93} INFO - 25/07/19 16:31:15 INFO SharedState: Warehouse path is 'file:/app/spark-warehouse'.
[2025-07-19T16:31:15.937+0000] {subprocess.py:93} INFO - 25/07/19 16:31:15 WARN MetricsConfig: Cannot locate configuration: tried hadoop-metrics2-s3a-file-system.properties,hadoop-metrics2.properties
[2025-07-19T16:31:15.943+0000] {subprocess.py:93} INFO - 25/07/19 16:31:15 INFO MetricsSystemImpl: Scheduled Metric snapshot period at 10 second(s).
[2025-07-19T16:31:15.943+0000] {subprocess.py:93} INFO - 25/07/19 16:31:15 INFO MetricsSystemImpl: s3a-file-system metrics system started
[2025-07-19T16:51:53.775+0000] {local_task_job_runner.py:115} ERROR - Received SIGTERM. Terminating subprocesses
[2025-07-19T16:51:53.876+0000] {process_utils.py:131} INFO - Sending 15 to group 732. PIDs of all processes in the group: [733, 732]
[2025-07-19T16:51:53.881+0000] {process_utils.py:86} INFO - Sending the signal 15 to group 732
[2025-07-19T16:51:53.905+0000] {taskinstance.py:1632} ERROR - Received SIGTERM. Terminating subprocesses.
[2025-07-19T16:51:53.933+0000] {subprocess.py:104} INFO - Sending SIGTERM signal to process group
[2025-07-19T16:51:55.454+0000] {standard_task_runner.py:104} ERROR - Failed to execute job 836 for task stream_to_bronze ((psycopg2.OperationalError) could not translate host name "postgres" to address: Name or service not known

(Background on this error at: https://sqlalche.me/e/14/e3q8); 732)
[2025-07-19T16:51:55.472+0000] {process_utils.py:79} INFO - Process psutil.Process(pid=733, status='terminated', started='16:31:12') (733) terminated with exit code None
[2025-07-19T16:51:55.473+0000] {process_utils.py:79} INFO - Process psutil.Process(pid=732, status='terminated', exitcode=1, started='16:31:12') (732) terminated with exit code 1
[2025-07-19T16:51:55.474+0000] {local_task_job_runner.py:228} INFO - Task exited with return code 143
[2025-07-19T16:51:55.483+0000] {taskinstance.py:2784} INFO - Skipping mini scheduling run due to exception: None
Traceback (most recent call last):
  File "/home/airflow/.local/lib/python3.8/site-packages/sqlalchemy/engine/base.py", line 3371, in _wrap_pool_connect
    return fn()
  File "/home/airflow/.local/lib/python3.8/site-packages/sqlalchemy/pool/base.py", line 327, in connect
    return _ConnectionFairy._checkout(self)
  File "/home/airflow/.local/lib/python3.8/site-packages/sqlalchemy/pool/base.py", line 894, in _checkout
    fairy = _ConnectionRecord.checkout(pool)
  File "/home/airflow/.local/lib/python3.8/site-packages/sqlalchemy/pool/base.py", line 493, in checkout
    rec = pool._do_get()
  File "/home/airflow/.local/lib/python3.8/site-packages/sqlalchemy/pool/impl.py", line 256, in _do_get
    return self._create_connection()
  File "/home/airflow/.local/lib/python3.8/site-packages/sqlalchemy/pool/base.py", line 273, in _create_connection
    return _ConnectionRecord(self)
  File "/home/airflow/.local/lib/python3.8/site-packages/sqlalchemy/pool/base.py", line 388, in __init__
    self.__connect()
  File "/home/airflow/.local/lib/python3.8/site-packages/sqlalchemy/pool/base.py", line 691, in __connect
    pool.logger.debug("Error on connect(): %s", e)
  File "/home/airflow/.local/lib/python3.8/site-packages/sqlalchemy/util/langhelpers.py", line 70, in __exit__
    compat.raise_(
  File "/home/airflow/.local/lib/python3.8/site-packages/sqlalchemy/util/compat.py", line 211, in raise_
    raise exception
  File "/home/airflow/.local/lib/python3.8/site-packages/sqlalchemy/pool/base.py", line 686, in __connect
    self.dbapi_connection = connection = pool._invoke_creator(self)
  File "/home/airflow/.local/lib/python3.8/site-packages/sqlalchemy/engine/create.py", line 574, in connect
    return dialect.connect(*cargs, **cparams)
  File "/home/airflow/.local/lib/python3.8/site-packages/sqlalchemy/engine/default.py", line 598, in connect
    return self.dbapi.connect(*cargs, **cparams)
  File "/home/airflow/.local/lib/python3.8/site-packages/psycopg2/__init__.py", line 122, in connect
    conn = _connect(dsn, connection_factory=connection_factory, **kwasync)
psycopg2.OperationalError: could not translate host name "postgres" to address: Name or service not known


The above exception was the direct cause of the following exception:

Traceback (most recent call last):
  File "/home/airflow/.local/lib/python3.8/site-packages/airflow/models/taskinstance.py", line 2733, in schedule_downstream_tasks
    dag_run = with_row_locks(
  File "/home/airflow/.local/lib/python3.8/site-packages/sqlalchemy/orm/query.py", line 2870, in one
    return self._iter().one()
  File "/home/airflow/.local/lib/python3.8/site-packages/sqlalchemy/orm/query.py", line 2916, in _iter
    result = self.session.execute(
  File "/home/airflow/.local/lib/python3.8/site-packages/sqlalchemy/orm/session.py", line 1716, in execute
    conn = self._connection_for_bind(bind)
  File "/home/airflow/.local/lib/python3.8/site-packages/sqlalchemy/orm/session.py", line 1555, in _connection_for_bind
    return self._transaction._connection_for_bind(
  File "/home/airflow/.local/lib/python3.8/site-packages/sqlalchemy/orm/session.py", line 750, in _connection_for_bind
    conn = bind.connect()
  File "/home/airflow/.local/lib/python3.8/site-packages/sqlalchemy/future/engine.py", line 406, in connect
    return super(Engine, self).connect()
  File "/home/airflow/.local/lib/python3.8/site-packages/sqlalchemy/engine/base.py", line 3325, in connect
    return self._connection_cls(self, close_with_result=close_with_result)
  File "/home/airflow/.local/lib/python3.8/site-packages/sqlalchemy/engine/base.py", line 96, in __init__
    else engine.raw_connection()
  File "/home/airflow/.local/lib/python3.8/site-packages/sqlalchemy/engine/base.py", line 3404, in raw_connection
    return self._wrap_pool_connect(self.pool.connect, _connection)
  File "/home/airflow/.local/lib/python3.8/site-packages/sqlalchemy/engine/base.py", line 3374, in _wrap_pool_connect
    Connection._handle_dbapi_exception_noconnection(
  File "/home/airflow/.local/lib/python3.8/site-packages/sqlalchemy/engine/base.py", line 2208, in _handle_dbapi_exception_noconnection
    util.raise_(
  File "/home/airflow/.local/lib/python3.8/site-packages/sqlalchemy/util/compat.py", line 211, in raise_
    raise exception
  File "/home/airflow/.local/lib/python3.8/site-packages/sqlalchemy/engine/base.py", line 3371, in _wrap_pool_connect
    return fn()
  File "/home/airflow/.local/lib/python3.8/site-packages/sqlalchemy/pool/base.py", line 327, in connect
    return _ConnectionFairy._checkout(self)
  File "/home/airflow/.local/lib/python3.8/site-packages/sqlalchemy/pool/base.py", line 894, in _checkout
    fairy = _ConnectionRecord.checkout(pool)
  File "/home/airflow/.local/lib/python3.8/site-packages/sqlalchemy/pool/base.py", line 493, in checkout
    rec = pool._do_get()
  File "/home/airflow/.local/lib/python3.8/site-packages/sqlalchemy/pool/impl.py", line 256, in _do_get
    return self._create_connection()
  File "/home/airflow/.local/lib/python3.8/site-packages/sqlalchemy/pool/base.py", line 273, in _create_connection
    return _ConnectionRecord(self)
  File "/home/airflow/.local/lib/python3.8/site-packages/sqlalchemy/pool/base.py", line 388, in __init__
    self.__connect()
  File "/home/airflow/.local/lib/python3.8/site-packages/sqlalchemy/pool/base.py", line 691, in __connect
    pool.logger.debug("Error on connect(): %s", e)
  File "/home/airflow/.local/lib/python3.8/site-packages/sqlalchemy/util/langhelpers.py", line 70, in __exit__
    compat.raise_(
  File "/home/airflow/.local/lib/python3.8/site-packages/sqlalchemy/util/compat.py", line 211, in raise_
    raise exception
  File "/home/airflow/.local/lib/python3.8/site-packages/sqlalchemy/pool/base.py", line 686, in __connect
    self.dbapi_connection = connection = pool._invoke_creator(self)
  File "/home/airflow/.local/lib/python3.8/site-packages/sqlalchemy/engine/create.py", line 574, in connect
    return dialect.connect(*cargs, **cparams)
  File "/home/airflow/.local/lib/python3.8/site-packages/sqlalchemy/engine/default.py", line 598, in connect
    return self.dbapi.connect(*cargs, **cparams)
  File "/home/airflow/.local/lib/python3.8/site-packages/psycopg2/__init__.py", line 122, in connect
    conn = _connect(dsn, connection_factory=connection_factory, **kwasync)
sqlalchemy.exc.OperationalError: (psycopg2.OperationalError) could not translate host name "postgres" to address: Name or service not known

(Background on this error at: https://sqlalche.me/e/14/e3q8)
[2025-07-19T16:51:55.506+0000] {job.py:219} ERROR - Job heartbeat got an exception
Traceback (most recent call last):
  File "/home/airflow/.local/lib/python3.8/site-packages/sqlalchemy/engine/base.py", line 3371, in _wrap_pool_connect
    return fn()
  File "/home/airflow/.local/lib/python3.8/site-packages/sqlalchemy/pool/base.py", line 327, in connect
    return _ConnectionFairy._checkout(self)
  File "/home/airflow/.local/lib/python3.8/site-packages/sqlalchemy/pool/base.py", line 894, in _checkout
    fairy = _ConnectionRecord.checkout(pool)
  File "/home/airflow/.local/lib/python3.8/site-packages/sqlalchemy/pool/base.py", line 493, in checkout
    rec = pool._do_get()
  File "/home/airflow/.local/lib/python3.8/site-packages/sqlalchemy/pool/impl.py", line 256, in _do_get
    return self._create_connection()
  File "/home/airflow/.local/lib/python3.8/site-packages/sqlalchemy/pool/base.py", line 273, in _create_connection
    return _ConnectionRecord(self)
  File "/home/airflow/.local/lib/python3.8/site-packages/sqlalchemy/pool/base.py", line 388, in __init__
    self.__connect()
  File "/home/airflow/.local/lib/python3.8/site-packages/sqlalchemy/pool/base.py", line 691, in __connect
    pool.logger.debug("Error on connect(): %s", e)
  File "/home/airflow/.local/lib/python3.8/site-packages/sqlalchemy/util/langhelpers.py", line 70, in __exit__
    compat.raise_(
  File "/home/airflow/.local/lib/python3.8/site-packages/sqlalchemy/util/compat.py", line 211, in raise_
    raise exception
  File "/home/airflow/.local/lib/python3.8/site-packages/sqlalchemy/pool/base.py", line 686, in __connect
    self.dbapi_connection = connection = pool._invoke_creator(self)
  File "/home/airflow/.local/lib/python3.8/site-packages/sqlalchemy/engine/create.py", line 574, in connect
    return dialect.connect(*cargs, **cparams)
  File "/home/airflow/.local/lib/python3.8/site-packages/sqlalchemy/engine/default.py", line 598, in connect
    return self.dbapi.connect(*cargs, **cparams)
  File "/home/airflow/.local/lib/python3.8/site-packages/psycopg2/__init__.py", line 122, in connect
    conn = _connect(dsn, connection_factory=connection_factory, **kwasync)
psycopg2.OperationalError: could not translate host name "postgres" to address: Name or service not known


The above exception was the direct cause of the following exception:

Traceback (most recent call last):
  File "/home/airflow/.local/lib/python3.8/site-packages/airflow/jobs/job.py", line 190, in heartbeat
    session.merge(self)
  File "/home/airflow/.local/lib/python3.8/site-packages/sqlalchemy/orm/session.py", line 3056, in merge
    return self._merge(
  File "/home/airflow/.local/lib/python3.8/site-packages/sqlalchemy/orm/session.py", line 3136, in _merge
    merged = self.get(
  File "/home/airflow/.local/lib/python3.8/site-packages/sqlalchemy/orm/session.py", line 2853, in get
    return self._get_impl(
  File "/home/airflow/.local/lib/python3.8/site-packages/sqlalchemy/orm/session.py", line 2975, in _get_impl
    return db_load_fn(
  File "/home/airflow/.local/lib/python3.8/site-packages/sqlalchemy/orm/loading.py", line 530, in load_on_pk_identity
    session.execute(
  File "/home/airflow/.local/lib/python3.8/site-packages/sqlalchemy/orm/session.py", line 1716, in execute
    conn = self._connection_for_bind(bind)
  File "/home/airflow/.local/lib/python3.8/site-packages/sqlalchemy/orm/session.py", line 1555, in _connection_for_bind
    return self._transaction._connection_for_bind(
  File "/home/airflow/.local/lib/python3.8/site-packages/sqlalchemy/orm/session.py", line 750, in _connection_for_bind
    conn = bind.connect()
  File "/home/airflow/.local/lib/python3.8/site-packages/sqlalchemy/future/engine.py", line 406, in connect
    return super(Engine, self).connect()
  File "/home/airflow/.local/lib/python3.8/site-packages/sqlalchemy/engine/base.py", line 3325, in connect
    return self._connection_cls(self, close_with_result=close_with_result)
  File "/home/airflow/.local/lib/python3.8/site-packages/sqlalchemy/engine/base.py", line 96, in __init__
    else engine.raw_connection()
  File "/home/airflow/.local/lib/python3.8/site-packages/sqlalchemy/engine/base.py", line 3404, in raw_connection
    return self._wrap_pool_connect(self.pool.connect, _connection)
  File "/home/airflow/.local/lib/python3.8/site-packages/sqlalchemy/engine/base.py", line 3374, in _wrap_pool_connect
    Connection._handle_dbapi_exception_noconnection(
  File "/home/airflow/.local/lib/python3.8/site-packages/sqlalchemy/engine/base.py", line 2208, in _handle_dbapi_exception_noconnection
    util.raise_(
  File "/home/airflow/.local/lib/python3.8/site-packages/sqlalchemy/util/compat.py", line 211, in raise_
    raise exception
  File "/home/airflow/.local/lib/python3.8/site-packages/sqlalchemy/engine/base.py", line 3371, in _wrap_pool_connect
    return fn()
  File "/home/airflow/.local/lib/python3.8/site-packages/sqlalchemy/pool/base.py", line 327, in connect
    return _ConnectionFairy._checkout(self)
  File "/home/airflow/.local/lib/python3.8/site-packages/sqlalchemy/pool/base.py", line 894, in _checkout
    fairy = _ConnectionRecord.checkout(pool)
  File "/home/airflow/.local/lib/python3.8/site-packages/sqlalchemy/pool/base.py", line 493, in checkout
    rec = pool._do_get()
  File "/home/airflow/.local/lib/python3.8/site-packages/sqlalchemy/pool/impl.py", line 256, in _do_get
    return self._create_connection()
  File "/home/airflow/.local/lib/python3.8/site-packages/sqlalchemy/pool/base.py", line 273, in _create_connection
    return _ConnectionRecord(self)
  File "/home/airflow/.local/lib/python3.8/site-packages/sqlalchemy/pool/base.py", line 388, in __init__
    self.__connect()
  File "/home/airflow/.local/lib/python3.8/site-packages/sqlalchemy/pool/base.py", line 691, in __connect
    pool.logger.debug("Error on connect(): %s", e)
  File "/home/airflow/.local/lib/python3.8/site-packages/sqlalchemy/util/langhelpers.py", line 70, in __exit__
    compat.raise_(
  File "/home/airflow/.local/lib/python3.8/site-packages/sqlalchemy/util/compat.py", line 211, in raise_
    raise exception
  File "/home/airflow/.local/lib/python3.8/site-packages/sqlalchemy/pool/base.py", line 686, in __connect
    self.dbapi_connection = connection = pool._invoke_creator(self)
  File "/home/airflow/.local/lib/python3.8/site-packages/sqlalchemy/engine/create.py", line 574, in connect
    return dialect.connect(*cargs, **cparams)
  File "/home/airflow/.local/lib/python3.8/site-packages/sqlalchemy/engine/default.py", line 598, in connect
    return self.dbapi.connect(*cargs, **cparams)
  File "/home/airflow/.local/lib/python3.8/site-packages/psycopg2/__init__.py", line 122, in connect
    conn = _connect(dsn, connection_factory=connection_factory, **kwasync)
sqlalchemy.exc.OperationalError: (psycopg2.OperationalError) could not translate host name "postgres" to address: Name or service not known

(Background on this error at: https://sqlalche.me/e/14/e3q8)
