[2025-07-18T14:38:40.770+0000] {taskinstance.py:1159} INFO - Dependencies all met for dep_context=non-requeueable deps ti=<TaskInstance: restaurant_pipeline.generate_json_files scheduled__2025-07-18T14:36:00+00:00 [queued]>
[2025-07-18T14:38:40.776+0000] {taskinstance.py:1159} INFO - Dependencies all met for dep_context=requeueable deps ti=<TaskInstance: restaurant_pipeline.generate_json_files scheduled__2025-07-18T14:36:00+00:00 [queued]>
[2025-07-18T14:38:40.777+0000] {taskinstance.py:1361} INFO - Starting attempt 1 of 1
[2025-07-18T14:38:40.782+0000] {taskinstance.py:1382} INFO - Executing <Task(PythonOperator): generate_json_files> on 2025-07-18 14:36:00+00:00
[2025-07-18T14:38:40.785+0000] {standard_task_runner.py:57} INFO - Started process 185 to run task
[2025-07-18T14:38:40.788+0000] {standard_task_runner.py:84} INFO - Running: ['***', 'tasks', 'run', 'restaurant_pipeline', 'generate_json_files', 'scheduled__2025-07-18T14:36:00+00:00', '--job-id', '4', '--raw', '--subdir', 'DAGS_FOLDER/restaurant_pipeline.py', '--cfg-path', '/tmp/tmp02ruu3lf']
[2025-07-18T14:38:40.792+0000] {standard_task_runner.py:85} INFO - Job 4: Subtask generate_json_files
[2025-07-18T14:38:40.832+0000] {task_command.py:416} INFO - Running <TaskInstance: restaurant_pipeline.generate_json_files scheduled__2025-07-18T14:36:00+00:00 [running]> on host 4dd4e0da2e3e
[2025-07-18T14:38:40.890+0000] {taskinstance.py:1662} INFO - Exporting env vars: AIRFLOW_CTX_DAG_OWNER='moran' AIRFLOW_CTX_DAG_ID='restaurant_pipeline' AIRFLOW_CTX_TASK_ID='generate_json_files' AIRFLOW_CTX_EXECUTION_DATE='2025-07-18T14:36:00+00:00' AIRFLOW_CTX_TRY_NUMBER='1' AIRFLOW_CTX_DAG_RUN_ID='scheduled__2025-07-18T14:36:00+00:00'
[2025-07-18T14:38:40.891+0000] {taskinstance.py:1937} ERROR - Task failed with exception
Traceback (most recent call last):
  File "/usr/local/lib/python3.8/pathlib.py", line 1288, in mkdir
    self._accessor.mkdir(self, mode)
FileNotFoundError: [Errno 2] No such file or directory: '/opt/streaming/messages'

During handling of the above exception, another exception occurred:

Traceback (most recent call last):
  File "/home/airflow/.local/lib/python3.8/site-packages/airflow/operators/python.py", line 192, in execute
    return_value = self.execute_callable()
  File "/home/airflow/.local/lib/python3.8/site-packages/airflow/operators/python.py", line 209, in execute_callable
    return self.python_callable(*self.op_args, **self.op_kwargs)
  File "/opt/airflow/dags/restaurant_pipeline.py", line 68, in write_json_files
    MSG_DIR.mkdir(parents=True, exist_ok=True)
  File "/usr/local/lib/python3.8/pathlib.py", line 1292, in mkdir
    self.parent.mkdir(parents=True, exist_ok=True)
  File "/usr/local/lib/python3.8/pathlib.py", line 1288, in mkdir
    self._accessor.mkdir(self, mode)
PermissionError: [Errno 13] Permission denied: '/opt/streaming'
[2025-07-18T14:38:40.896+0000] {taskinstance.py:1400} INFO - Marking task as FAILED. dag_id=restaurant_pipeline, task_id=generate_json_files, execution_date=20250718T143600, start_date=20250718T143840, end_date=20250718T143840
[2025-07-18T14:38:40.902+0000] {standard_task_runner.py:104} ERROR - Failed to execute job 4 for task generate_json_files ([Errno 13] Permission denied: '/opt/streaming'; 185)
[2025-07-18T14:38:40.925+0000] {local_task_job_runner.py:228} INFO - Task exited with return code 1
[2025-07-18T14:38:40.951+0000] {taskinstance.py:2778} INFO - 0 downstream tasks scheduled from follow-on schedule check
