[2025-07-19T17:48:51.094+0000] {taskinstance.py:1159} INFO - Dependencies all met for dep_context=non-requeueable deps ti=<TaskInstance: restaurant_pipeline.send_to_kafka scheduled__2025-07-19T17:32:00+00:00 [queued]>
[2025-07-19T17:48:51.098+0000] {taskinstance.py:1159} INFO - Dependencies all met for dep_context=requeueable deps ti=<TaskInstance: restaurant_pipeline.send_to_kafka scheduled__2025-07-19T17:32:00+00:00 [queued]>
[2025-07-19T17:48:51.099+0000] {taskinstance.py:1361} INFO - Starting attempt 1 of 1
[2025-07-19T17:48:51.105+0000] {taskinstance.py:1382} INFO - Executing <Task(BashOperator): send_to_kafka> on 2025-07-19 17:32:00+00:00
[2025-07-19T17:48:51.106+0000] {standard_task_runner.py:57} INFO - Started process 179 to run task
[2025-07-19T17:48:51.108+0000] {standard_task_runner.py:84} INFO - Running: ['***', 'tasks', 'run', 'restaurant_pipeline', 'send_to_kafka', 'scheduled__2025-07-19T17:32:00+00:00', '--job-id', '894', '--raw', '--subdir', 'DAGS_FOLDER/restaurant_pipeline.py', '--cfg-path', '/tmp/tmpcjfk9pfa']
[2025-07-19T17:48:51.110+0000] {standard_task_runner.py:85} INFO - Job 894: Subtask send_to_kafka
[2025-07-19T17:48:51.131+0000] {task_command.py:416} INFO - Running <TaskInstance: restaurant_pipeline.send_to_kafka scheduled__2025-07-19T17:32:00+00:00 [running]> on host 03593c79cc17
[2025-07-19T17:48:51.172+0000] {taskinstance.py:1662} INFO - Exporting env vars: AIRFLOW_CTX_DAG_EMAIL='your@email.com' AIRFLOW_CTX_DAG_OWNER='moran' AIRFLOW_CTX_DAG_ID='restaurant_pipeline' AIRFLOW_CTX_TASK_ID='send_to_kafka' AIRFLOW_CTX_EXECUTION_DATE='2025-07-19T17:32:00+00:00' AIRFLOW_CTX_TRY_NUMBER='1' AIRFLOW_CTX_DAG_RUN_ID='scheduled__2025-07-19T17:32:00+00:00'
[2025-07-19T17:48:51.173+0000] {subprocess.py:63} INFO - Tmp dir root location: /tmp
[2025-07-19T17:48:51.173+0000] {subprocess.py:75} INFO - Running command: ['/bin/bash', '-c', 'python /opt/streaming/producer.py']
[2025-07-19T17:48:51.176+0000] {subprocess.py:86} INFO - Output:
[2025-07-19T17:48:53.523+0000] {subprocess.py:93} INFO - Traceback (most recent call last):
[2025-07-19T17:48:53.525+0000] {subprocess.py:93} INFO -   File "/opt/streaming/producer.py", line 7, in <module>
[2025-07-19T17:48:53.525+0000] {subprocess.py:93} INFO -     producer = KafkaProducer(
[2025-07-19T17:48:53.525+0000] {subprocess.py:93} INFO -   File "/home/***/.local/lib/python3.8/site-packages/kafka/producer/kafka.py", line 481, in __init__
[2025-07-19T17:48:53.525+0000] {subprocess.py:93} INFO -     client = self.config['kafka_client'](
[2025-07-19T17:48:53.526+0000] {subprocess.py:93} INFO -   File "/home/***/.local/lib/python3.8/site-packages/kafka/client_async.py", line 262, in __init__
[2025-07-19T17:48:53.526+0000] {subprocess.py:93} INFO -     self.config['api_version'] = self.check_version()
[2025-07-19T17:48:53.527+0000] {subprocess.py:93} INFO -   File "/home/***/.local/lib/python3.8/site-packages/kafka/client_async.py", line 1074, in check_version
[2025-07-19T17:48:53.528+0000] {subprocess.py:93} INFO -     raise Errors.NoBrokersAvailable()
[2025-07-19T17:48:53.528+0000] {subprocess.py:93} INFO - kafka.errors.NoBrokersAvailable: NoBrokersAvailable
[2025-07-19T17:48:53.568+0000] {subprocess.py:97} INFO - Command exited with return code 1
[2025-07-19T17:48:53.578+0000] {taskinstance.py:1937} ERROR - Task failed with exception
Traceback (most recent call last):
  File "/home/airflow/.local/lib/python3.8/site-packages/airflow/operators/bash.py", line 210, in execute
    raise AirflowException(
airflow.exceptions.AirflowException: Bash command failed. The command returned a non-zero exit code 1.
[2025-07-19T17:48:53.582+0000] {taskinstance.py:1400} INFO - Marking task as FAILED. dag_id=restaurant_pipeline, task_id=send_to_kafka, execution_date=20250719T173200, start_date=20250719T174851, end_date=20250719T174853
[2025-07-19T17:48:53.598+0000] {logging_mixin.py:154} WARNING - /home/***/.local/lib/python3.8/site-packages/***/utils/email.py:154 RemovedInAirflow3Warning: Fetching SMTP credentials from configuration variables will be deprecated in a future release. Please set credentials using a connection instead.
[2025-07-19T17:48:53.598+0000] {configuration.py:1050} WARNING - section/key [smtp/smtp_user] not found in config
[2025-07-19T17:48:53.598+0000] {email.py:270} INFO - Email alerting: attempt 1
[2025-07-19T17:48:53.602+0000] {configuration.py:1050} WARNING - section/key [smtp/smtp_user] not found in config
[2025-07-19T17:48:53.602+0000] {email.py:270} INFO - Email alerting: attempt 1
[2025-07-19T17:48:53.602+0000] {taskinstance.py:2007} ERROR - Failed to send email to: ['your@email.com']
Traceback (most recent call last):
  File "/home/airflow/.local/lib/python3.8/site-packages/airflow/models/taskinstance.py", line 1518, in _run_raw_task
    self._execute_task_with_callbacks(context, test_mode, session=session)
  File "/home/airflow/.local/lib/python3.8/site-packages/airflow/models/taskinstance.py", line 1681, in _execute_task_with_callbacks
    result = self._execute_task(context, task_orig)
  File "/home/airflow/.local/lib/python3.8/site-packages/airflow/models/taskinstance.py", line 1744, in _execute_task
    result = execute_callable(context=context, **execute_callable_kwargs)
  File "/home/airflow/.local/lib/python3.8/site-packages/airflow/operators/bash.py", line 210, in execute
    raise AirflowException(
airflow.exceptions.AirflowException: Bash command failed. The command returned a non-zero exit code 1.

During handling of the above exception, another exception occurred:

Traceback (most recent call last):
  File "/home/airflow/.local/lib/python3.8/site-packages/airflow/models/taskinstance.py", line 2420, in email_alert
    send_email(task.email, subject, html_content)
  File "/home/airflow/.local/lib/python3.8/site-packages/airflow/utils/email.py", line 80, in send_email
    return backend(
  File "/home/airflow/.local/lib/python3.8/site-packages/airflow/utils/email.py", line 154, in send_email_smtp
    send_mime_email(e_from=mail_from, e_to=recipients, mime_msg=msg, conn_id=conn_id, dryrun=dryrun)
  File "/home/airflow/.local/lib/python3.8/site-packages/airflow/utils/email.py", line 272, in send_mime_email
    smtp_conn = _get_smtp_connection(smtp_host, smtp_port, smtp_timeout, smtp_ssl)
  File "/home/airflow/.local/lib/python3.8/site-packages/airflow/utils/email.py", line 316, in _get_smtp_connection
    return smtplib.SMTP(host=host, port=port, timeout=timeout)
  File "/usr/local/lib/python3.8/smtplib.py", line 255, in __init__
    (code, msg) = self.connect(host, port)
  File "/usr/local/lib/python3.8/smtplib.py", line 339, in connect
    self.sock = self._get_socket(host, port, self.timeout)
  File "/usr/local/lib/python3.8/smtplib.py", line 310, in _get_socket
    return socket.create_connection((host, port), timeout,
  File "/usr/local/lib/python3.8/socket.py", line 808, in create_connection
    raise err
  File "/usr/local/lib/python3.8/socket.py", line 796, in create_connection
    sock.connect(sa)
ConnectionRefusedError: [Errno 111] Connection refused

During handling of the above exception, another exception occurred:

Traceback (most recent call last):
  File "/home/airflow/.local/lib/python3.8/site-packages/airflow/models/taskinstance.py", line 2005, in handle_failure
    self.email_alert(error, task)
  File "/home/airflow/.local/lib/python3.8/site-packages/airflow/models/taskinstance.py", line 2422, in email_alert
    send_email(task.email, subject, html_content_err)
  File "/home/airflow/.local/lib/python3.8/site-packages/airflow/utils/email.py", line 80, in send_email
    return backend(
  File "/home/airflow/.local/lib/python3.8/site-packages/airflow/utils/email.py", line 154, in send_email_smtp
    send_mime_email(e_from=mail_from, e_to=recipients, mime_msg=msg, conn_id=conn_id, dryrun=dryrun)
  File "/home/airflow/.local/lib/python3.8/site-packages/airflow/utils/email.py", line 272, in send_mime_email
    smtp_conn = _get_smtp_connection(smtp_host, smtp_port, smtp_timeout, smtp_ssl)
  File "/home/airflow/.local/lib/python3.8/site-packages/airflow/utils/email.py", line 316, in _get_smtp_connection
    return smtplib.SMTP(host=host, port=port, timeout=timeout)
  File "/usr/local/lib/python3.8/smtplib.py", line 255, in __init__
    (code, msg) = self.connect(host, port)
  File "/usr/local/lib/python3.8/smtplib.py", line 339, in connect
    self.sock = self._get_socket(host, port, self.timeout)
  File "/usr/local/lib/python3.8/smtplib.py", line 310, in _get_socket
    return socket.create_connection((host, port), timeout,
  File "/usr/local/lib/python3.8/socket.py", line 808, in create_connection
    raise err
  File "/usr/local/lib/python3.8/socket.py", line 796, in create_connection
    sock.connect(sa)
ConnectionRefusedError: [Errno 111] Connection refused
[2025-07-19T17:48:53.611+0000] {standard_task_runner.py:104} ERROR - Failed to execute job 894 for task send_to_kafka (Bash command failed. The command returned a non-zero exit code 1.; 179)
[2025-07-19T17:48:53.627+0000] {local_task_job_runner.py:228} INFO - Task exited with return code 1
[2025-07-19T17:48:53.651+0000] {taskinstance.py:2778} INFO - 0 downstream tasks scheduled from follow-on schedule check
